---
title: "Gestion des exceptions"
---

## Définition

**Une exception est une erreur** qui se produit pendant l'exécution du programme, contrairement aux erreurs de syntaxe qui sont détectées avant l'exécution. Les exceptions peuvent être dues à diverses raisons, telles que des entrées invalides, des opérations mathématiques impossibles, des manipulations de fichiers incorrectes, etc.

Voici quelques **exemples d'exceptions** fréquemment rencontrées :

* ```IndexError``` : Se produit lorsqu'on tente d'accéder à un index qui n'existe pas dans une séquence (comme une liste ou un tuple).

* ```ValueError``` : Apparaît lorsqu'une fonction reçoit un argument de type correct mais d'une valeur inappropriée.

* ```TypeError``` : Se produit lorsqu'une opération ou fonction est appliquée à un objet d'un type inapproprié.

* ```FileNotFoundError``` : Levée lorsqu'une tentative de lecture d'un fichier échoue parce que le fichier n'existe pas.

* ```ZeroDivisionError``` : Se produit lorsqu'une division par zéro est tentée.

* ```NameError``` : Se produit lorsqu'une variable n'est pas définie dans le contexte actuel.


## Traitement des exceptions

**La gestion des exceptions** est un aspect crucial de la programmation pour plusieurs raisons :

* **Robustesse** : Elle permet à un programme de gérer des situations d'erreur de manière gracieuse sans s'arrêter brusquement.
* **Contrôle du Flux** : Elle offre un moyen de diriger le flux d'un programme lorsque des situations exceptionnelles se produisent.
* **Débogage Facilité** : Elle aide à identifier les causes des erreurs et à les gérer efficacement.
* **Sécurité** : Elle permet de gérer des situations potentiellement dangereuses, comme la lecture de fichiers corrompus ou la gestion de données utilisateur erronées.

### Try-Except

La syntaxe de base pour la gestion des exceptions en Python utilise les instructions ```try``` et ```except```.

Vous pouvez avoir plusieurs blocs ```except``` pour gérer différents types d'exceptions. Cela permet de réagir de manière appropriée à différentes erreurs qui peuvent survenir.

L'utilisation de plusieurs blocs ```except``` permet de donner des réponses spécifiques à chaque type d'erreur, améliorant ainsi la lisibilité et la maintenance du code.

### Finally

Le bloc ```finally``` en Python est utilisé pour définir des actions qui doivent être exécutées après les blocs ```try``` et ```except```, peu importe si une exception a été levée ou non.

Ce bloc est souvent utilisé pour des opérations de nettoyage qui doivent s'exécuter dans tous les cas, comme la fermeture de fichiers ou la libération de ressources externes.


### Else

Utilisez ```else``` lorsque vous avez besoin d'exécuter du code qui ne doit s'exécuter que si le bloc ```tr```v s'est exécuté sans erreur, mais avant d'exécuter le code dans le bloc ```finally```.


## Assertions
L'instruction ```assert``` est utilisée pour tester si une condition est vraie. Si la condition est fausse, ```AssertionError``` est levée.

Les assertions sont principalement utilisées comme un moyen de débogage, pour vérifier des conditions internes, tandis que les exceptions sont utilisées pour gérer des erreurs et des conditions exceptionnelles dans le flux normal du programme.


## Raise

L'instruction ```raise``` en Python est un outil crucial pour la gestion des exceptions, permettant aux développeurs de déclencher explicitement des exceptions lorsqu'une condition spécifique se produit dans le programme.

Les exceptions levées avec ```raise``` peuvent être capturées et gérées en amont, permettant aux développeurs de réagir de manière appropriée aux différents types de problèmes qui peuvent survenir, améliorant ainsi la robustesse et la fiabilité du code.


## **En résumé**

Voici quelques-unes des exceptions intégrées courantes en programmation Python ainsi que les erreurs qui les provoquent.

|Exception | Cause de l'erreur |
|---------|----------|----------|
| AsseretionError| Levée lorsque l'instruction assert échoue | 
| AttributeError | Levée lorsque l'assignation ou la référence à un attribut échoue |
| EOFError | Levée lorsque input() atteint la fin du fichier |
| FloatingPointError | Levée lorsqu'une opération sur les nombres à virgule flottante échoue |
| GeneratorExit | Levée lorsque la méthode close() d'un générateur est appelée |
| ImportError | Levée lorsque le module importé n'est pas trouvé |
| IndexError | Levée lorsque l'index d'une séquence est hors de portée |
| KeyError | Levée lorsque une clé n'est pas trouvée dans un dictionnaire |
| KeyboardInterrupt | Levée lorsque l'utilisateur appuie sur la touche d'interruption (Ctrl+C ou Suppr) |
| MemoryError | Levée lorsqu'une opération manque de mémoire |
| NameError | Levée lorsqu'une variable n'est pas trouvée dans la portée locale ou globale |
| NotImplementedError | evée par des méthodes abstraites |
| OSError | Levée lorsqu'une opération système provoque une erreur liée au système |
| OverflowError | Levée lorsque le résultat d'une opération arithmétique est trop grand pour être représenté |
| ReferenceError | Levée lorsqu'une référence faible est utilisée pour accéder à un référent collecté par le ramasse-miette |
| RuntimeError | Levée lorsqu'une erreur ne rentre dans aucune autre catégorie |
| StopIteration | Levée par next() pour indiquer qu'il n'y a plus d'élément à renvoyer par l'itérateur |
| SyntaxError | Levée par l'analyseur lorsque une erreur de syntaxe est rencontrée |
| IndentationError | Levée lorsqu'il y a une indentation incorrecte |
| TabError | Levée lorsque l'indentation est composée de tabulations et d'espaces inconsistants |
| SystemError | Levée lorsque l'interpréteur détecte une erreur interne |
| SystemExit | Levée par la fonction sys.exit() |
| TypeError | Levée lorsqu'une fonction ou une opération est appliquée à un objet de type incorrect |
| UnboundLocalError | Levée lorsqu'une référence est faite à une variable locale dans une fonction ou une méthode, mais aucune valeur n'a été liée à cette variable |
| UnicodeDecodeError | Levée lorsqu'une erreur liée à Unicode se produit pendant le décodage |
| ValueError | Levée lorsqu'une fonction reçoit un argument de type correct mais de valeur incorrecte |
| ZeroDivisionError | Levée lorsque le deuxième opérande de l'opération de division ou de modulo est zéro |


Nous pouvons voir toutes les exceptions intégrées en utilisant la fonction locale intégrée comme suit :

```print(dir(locals()['__builtins__']))```